
GTCEuStartupEvents.registry('gtceu:recipe_type', event => {
    event.create('gate_assembly')
        .category('gate_assembly')
        .setEUIO('in')
        .setMaxIOSize(6, 1, 3, 0)
        .setSound(GTSoundEntries.ASSEMBLER);
});

GTCEuStartupEvents.registry('gtceu:machine', event => {
    event.create('gate_assembly', 'multiblock')
        .rotationState(RotationState.NON_Y_AXIS)
        .recipeType('gate_assembly')
        .recipeModifiers([GTRecipeModifiers.OC_PERFECT])
        .pattern(definition => FactoryBlockPattern.start()	
            .aisle("###############HHHHHHHHH###############", "###############HHHHHHHHH###############", "#######################################", "#######################################", "#######################################", "#######################################", "#######################################", "#######################################", "#######################################", "#######################################", "#######################################", "###############JJJJJJJJJ###############", "#######################################", "#######################################", "#######################################", "#######################################") 
            .aisle("############HHHJJJJJJJJJHHH############", "############HHHJJJLLLJJJHHH############", "#################KMMMK#################", "#################KMMMK#################", "#################KMMMK#################", "#################K#I#K#################", "#################K#I#K#################", "#################K#I#K#################", "#################KMMMK#################", "#################KMMMK#################", "#################KMMMK#################", "############JJJJJJJJJJJJJJJ############", "##################K#K##################", "#######################################", "#######################################", "#######################################") 
            .aisle("#########HHHJJJJJJJJJJJJJJJHHH#########", "#########HHHJJJJDDLDLDDDJJJHHH#########", "############K#####MMM#####K############", "############K#####MMM#####K############", "############K#####MMM#####K############", "############K#####IDI#####K############", "############K#####ICI#####K############", "############K#####IDI#####K############", "############K#####MMM#####K############", "############K#####MMM#####K############", "############K#####MMM#####K############", "#########JJJJJJJJJJJJJJJJJJJJJ#########", "##################K#K##################", "#######################################", "#######################################", "#######################################") 
            .aisle("########HJJJJJJJJJJJJJJJJJJJJJH########", "########HJLLLDDDJJLLLJJJDDLLLJH########", "##########MMM####KMMMK####MMM##########", "##########MMM####KMMMK####MMM##########", "##########MMM####KMMMK####MMM##########", "###########I#####K#I#K#####I###########", "###########I#####K#I#K#####I###########", "###########I#####K#I#K#####I###########", "##########MMM####KMMMK####MMM##########", "##########MMM####KMMMK####MMM##########", "##########MMM####KMMMK####MMM##########", "########JJJJJJJJJJJJJJJJJJJJJJJ########", "##################KGK##################", "#######################################", "#######################################", "#######################################") 
            .aisle("######HHJJJJJJJJHHJJJHHJJJJJJJJHH######", "######HHJJLDLJJJHHJDJHHJJJLDLJJHH######", "#########KMMMK###########KMMMK#########", "#########KMMMK###########KMMMK#########", "#########KMMMK###########KMMMK#########", "#########KIDIK###########KIDIK#########", "#########KICIK###########KICIK#########", "#########KIDIK###########KIDIK#########", "#########KMMMK###########KMMMK#########", "#########KMMMK###########KMMMK#########", "#########KMMMK###########KMMMK#########", "######JJJJJJJJJJJJJJJJJJJJJJJJJJJ######", "##################K#K##################", "#######################################", "#######################################", "#######################################") 
            .aisle("#####HJJJJJJJHHH##HJH##HHHJJJJJJJH#####", "#####HJJDDLLLHHH##HDH##HHHLLLDDJJH#####", "##########MMM#############MMM##########", "##########MMM#############MMM##########", "##########MMM#############MMM##########", "###########I###############I###########", "###########I###############I###########", "###########I###############I###########", "##########MMM#############MMM##########", "##########MMM#############MMM##########", "##########MMM#############MMM##########", "#####JJJJJJJJJJJ#######JJJJJJJJJJJ#####", "#######################################", "##################K#K##################", "#######################################", "#######################################") 
            .aisle("####HJJJJJJHH#####HJH#####HHJJJJJJH####", "####HJJDJJJHH#####HDH#####HHJJJDJJH####", "##########K#################K##########", "##########K#################K##########", "##########K#################K##########", "##########K#################K##########", "##########K#################K##########", "##########K#################K##########", "##########K#################K##########", "##########K#################K##########", "##########K#################K##########", "####JJJJJJJJJ#############JJJJJJJJJ####", "#######################################", "##################K#K##################", "#######################################", "#######################################") 
            .aisle("###HJJJJJHH#######HJH#######HHJJJJJH###", "###HJJDJJHH#######HDH#######HHJJDJJH###", "#####K###########################K#####", "#####K###########################K#####", "#####K###########################K#####", "#####K###########################K#####", "#####K###########################K#####", "#####K###########################K#####", "#####K###########################K#####", "#####K###########################K#####", "#####K###########################K#####", "###JJJJJJJJ#################JJJJJJJJ###", "#######################################", "##################K#K##################", "#######################################", "#######################################") 
            .aisle("##HJJJJJH#########HJH#########HJJJJJH##", "##HLLLJJH#########HDH#########HJJLLLH##", "###MMMK#########################KMMM###", "###MMMK#########################KMMM###", "###MMMK#########################KMMM###", "####I#K#########################K#I####", "####I#K#########################K#I####", "####I#K#########################K#I####", "###MMMK#########################KMMM###", "###MMMK#########################KMMM###", "###MMMK#########################KMMM###", "###JJJJJJ#####################JJJJJJ###", "#######################################", "#######################################", "##################K#K##################", "#######################################") 	
            .aisle("##HJJJJH########HHJJJHH########HJJJJH##", "##HLDLJH########HHJDJHH########HJLDLH##", "###MMM###########################MMM###", "###MMM###########################MMM###", "###MMM###########################MMM###", "###IDI###########################IDI###", "###ICI###########################ICI###", "###IDI###########################IDI###", "###MMM###########################MMM###", "###MMM###########################MMM###", "###MMM###########################MMM###", "##JJJJJJ#######################JJJJJJ##", "#######################################", "#######################################", "#################KKKKK#################", "#######################################") 
            .aisle("#HJJJJH######HHHJJJJJJJHHH######HJJJJH#", "#HJLLLH######HHHJJJDJJJHHH######HLLLJH#", "##KMMM###########################MMMK##", "##KMMM###########################MMMK##", "##KMMM###########################MMMK##", "##K#I#############################I#K##", "##K#I#############################I#K##", "##K#I#############################I#K##", "##KMMM###########################MMMK##", "##KMMM###########################MMMK##", "##KMMM###########################MMMK##", "#JJJJJJ#########################JJJJJJ#", "#######################################", "#######################################", "###############KK#K#K#KK###############", "#######################################") 
            .aisle("#HJJJJH####HHJJJJJJJJJJJJJHH####HJJJJH#", "#HJDJJH####HHJJJJJJDJJJJJJHH####HJJDJH#", "####K#############################K####", "####K#############################K####", "####K#############################K####", "####K#############################K####", "####K#############################K####", "####K#############################K####", "####K#############################K####", "####K#############################K####", "####K#############################K####", "#JJJJJJ#########################JJJJJJ#", "#######################################", "#######################################", "#############KK#########KK#############", "##################K#K##################") 
            .aisle("#HJJJH####HJJJJJJJJJJJJJJJJJH####HJJJH#", "#HJDJH####HJJJJBBBJDJBBBJJJJH####HJDJH#", "#######################################", "#######################################", "#######################################", "#######################################", "#######################################", "#######################################", "#######################################", "#######################################", "#######################################", "#JJJJJ###########################JJJJJ#", "#######################################", "#######################################", "############KK###########KK############", "##################K#K##################") 
            .aisle("HJJJJH###HJJJJJJJJJJJJJJJJJJJH###HJJJJH", "HJDJJH###HJJBBJJJJJGJJJJJBBJJH###HHJDJH", "#######################################", "#######################################", "#######################################", "#######################################", "#######################################", "#######################################", "#######################################", "#######################################", "#######################################", "JJJJJJ###########################JJJJJJ", "#######################################", "#######################################", "############K#############K############", "##################K#K##################") 
            .aisle("HJJJH####HJJJJJJJJJJJJJJJJJJJH####HJJJH", "HJDJH####HJJBJJJFFDGDEEJJJBJJH####HJDJH", "#K#K###############K###############K#K#", "#K#K###############################K#K#", "#K#K###############################K#K#", "#K#K###############################K#K#", "#K#K###############################K#K#", "#K#K###############################K#K#", "#K#K###############################K#K#", "#K#K###############################K#K#", "#K#K###############################K#K#", "JJJJJ#############################JJJJJ", "###################K###################", "###################K###################", "###########K######JJJ######K###########", "##################JJJ##################") 
            .aisle("HJJJH###HJJJJJJJJJJJJJJJJJJJJJH###HJJJH", "HLLLH###HJJJBJFFFCCCCCEEEJBJJJH###HLLLH", "#MMM##############KKK##############MMM#", "#MMM##############KKK##############MMM#", "#MMM###############K###############MMM#", "##I################K################I##", "##I#################################I##", "##I#################################I##", "#MMM###############################MMM#", "#MMM###############################MMM#", "#MMM###############################MMM#", "JJJJJ##############K##############JJJJJ", "##################KLK##################", "##################KLK##################", "###########K#####JJDJJ#####K###########", "#################JAAAJ#################") 
            .aisle("HJJJH###HJJJJJJJJJJJJJJJJJJJJJH###HJJJH", "HLDLH###HJJJJJDDCCGDGCCDDJJJJJH###HLDLH", "#MMM#############KKDKK#############MMM#", "#MMM##############KDK##############MMM#", "#MMM##############KDK##############MMM#", "#IDI##############KDK##############IDI#", "#ICI###############@###############ICI#", "#IDI###############K###############IDI#", "#MMM###############N###############MMM#", "#MMM###############K###############MMM#", "#MMM###############D###############MMM#", "JJJJJ#############KDK#############JJJJJ", "#KKKK############KLDLK############KKKK#", "#####KKKK########KLDLK########KKKK#####", "#########KKKKK###JDDDJ###KKKKK#########", "##############KKKJAAAJKKK##############") 	
            .aisle("HJJJH###HJJJJJJJJJJJJJJJJJJJJJH###HJJJH", "HLLLH###HJJJBJEEECCCCCFFFJBJJJH###HLLLH", "#MMM##############KKK##############MMM#", "#MMM##############KKK##############MMM#", "#MMM###############K###############MMM#", "##I################K################I##", "##I#################################I##", "##I#################################I##", "#MMM###############################MMM#", "#MMM###############################MMM#", "#MMM###############################MMM#", "JJJJJ##############K##############JJJJJ", "##################KLK##################", "##################KLK##################", "###########K#####JJDJJ#####K###########", "#################JAAAJ#################") 
            .aisle("HJJJH####HJJJJJJJJJJJJJJJJJJJH####HJJJH", "HJDJH####HJJBJJJEEDGDFFJJJBJJH####HJDJH", "#K#K###############K###############K#K#", "#K#K###############################K#K#", "#K#K###############################K#K#", "#K#K###############################K#K#", "#K#K###############################K#K#", "#K#K###############################K#K#", "#K#K###############################K#K#", "#K#K###############################K#K#", "#K#K###############################K#K#", "JJJJJ#############################JJJJJ", "###################K###################", "###################K###################", "###########K######JJJ######K###########", "##################JJJ##################") 
            .aisle("HJJJJH###HJJJJJJJJJJJJJJJJJJJH###HJJJJH", "HJDJJH###HJJBBJJJJJGJJJJJBBJJH###HJJDJH", "#######################################", "#######################################", "#######################################", "#######################################", "#######################################", "#######################################", "#######################################", "#######################################", "#######################################", "JJJJJJ###########################JJJJJJ", "#######################################", "#######################################", "############K#############K############", "##################K#K##################") 
            .aisle("#HJJJH####HJJJJJJJJJJJJJJJJJH####HJJJH#", "#HJDJH####HJJJJBBBJDJBBBJJJJH####HJDJH#", "#######################################", "#######################################", "#######################################", "#######################################", "#######################################", "#######################################", "#######################################", "#######################################", "#######################################", "#JJJJJ###########################JJJJJ#", "#######################################", "#######################################", "############KK###########KK############", "##################K#K##################") 
            .aisle("#HJJJJH####HHJJJJJJJJJJJJJHH####HJJJJH#", "#HJDJJH####HHJJJJJJDJJJJJJHH####HJJDJH#", "####K#############################K####", "####K#############################K####", "####K#############################K####", "####K#############################K####", "####K#############################K####", "####K#############################K####", "####K#############################K####", "####K#############################K####", "####K#############################K####", "#JJJJJJ#########################JJJJJJ#", "#######################################", "#######################################", "#############KK#########KK#############", "##################K#K##################") 
            .aisle("#HJJJJH######HHHJJJJJJJHHH######HJJJJH#", "#HJLLLH######HHHJJJDJJJHHH######HLLLJH#", "##KMMM###########################MMMK##", "##KMMM###########################MMMK##", "##KMMM###########################MMMK##", "##K#I#############################I#K##", "##K#I#############################I#K##", "##K#I#############################I#K##", "##KMMM###########################MMMK##", "##KMMM###########################MMMK##", "##KMMM###########################MMMK##", "#JJJJJJ#########################JJJJJJ#", "#######################################", "#######################################", "###############KK#K#K#KK###############", "#######################################") 
            .aisle("##HJJJJH########HHJJJHH########HJJJJH##", "##HLDLJH########HHJDJHH########HJLDLH##", "###MMM###########################MMM###", "###MMM###########################MMM###", "###MMM###########################MMM###", "###IDI###########################IDI###", "###ICI###########################ICI###", "###IDI###########################IDI###", "###MMM###########################MMM###", "###MMM###########################MMM###", "###MMM###########################MMM###", "##JJJJJJ#######################JJJJJJ##", "#######################################", "#######################################", "#################KKKKK#################", "#######################################") 
            .aisle("##HJJJJJH#########HJH#########HJJJJJH##", "##HLLLJJH#########HDH#########HJJLLLH##", "###MMMK#########################KMMM###", "###MMMK#########################KMMM###", "###MMMK#########################KMMM###", "####I#K#########################K#I####", "####I#K#########################K#I####", "####I#K#########################K#I####", "###MMMK#########################KMMM###", "###MMMK#########################KMMM###", "###MMMK#########################KMMM###", "###JJJJJJ#####################JJJJJJ###", "#######################################", "#######################################", "##################K#K##################", "#######################################") 	
            .aisle("###HJJJJJHH#######HJH#######HHJJJJJH###", "###HJJDJJHH#######HDH#######HHJJDJJH###", "#####K###########################K#####", "#####K###########################K#####", "#####K###########################K#####", "#####K###########################K#####", "#####K###########################K#####", "#####K###########################K#####", "#####K###########################K#####", "#####K###########################K#####", "#####K###########################K#####", "###JJJJJJJJ#################JJJJJJJJ###", "#######################################", "##################K#K##################", "#######################################", "#######################################") 
            .aisle("####HJJJJJJHH#####HJH#####HHJJJJJJH####", "####HJJDJJJHH#####HDH#####HHJJJDJJH####", "##########K#################K##########", "##########K#################K##########", "##########K#################K##########", "##########K#################K##########", "##########K#################K##########", "##########K#################K##########", "##########K#################K##########", "##########K#################K##########", "##########K#################K##########", "####JJJJJJJJJ#############JJJJJJJJJ####", "#######################################", "##################K#K##################", "#######################################", "#######################################") 
            .aisle("#####HJJJJJJJHHH##HJH##HHHJJJJJJJH#####", "#####HJJDDLLLHHH##HDH##HHHLLLDDJJH#####", "##########MMM#############MMM##########", "##########MMM#############MMM##########", "##########MMM#############MMM##########", "###########I###############I###########", "###########I###############I###########", "###########I###############I###########", "##########MMM#############MMM##########", "##########MMM#############MMM##########", "##########MMM#############MMM##########", "#####JJJJJJJJJJJ#######JJJJJJJJJJJ#####", "#######################################", "##################K#K##################", "#######################################", "#######################################") 
            .aisle("######HHJJJJJJJJHHJJJHHJJJJJJJJHH######", "######HHJJLDLJJJHHJDJHHJJJLDLJJHH######", "#########KMMMK###########KMMMK#########", "#########KMMMK###########KMMMK#########", "#########KMMMK###########KMMMK#########", "#########KIDIK###########KIDIK#########", "#########KICIK###########KICIK#########", "#########KIDIK###########KIDIK#########", "#########KMMMK###########KMMMK#########", "#########KMMMK###########KMMMK#########", "#########KMMMK###########KMMMK#########", "######JJJJJJJJJJJJJJJJJJJJJJJJJJJ######", "##################K#K##################", "#######################################", "#######################################", "#######################################") 
            .aisle("########HJJJJJJJJJJJJJJJJJJJJJH########", "########HJLLLDDJJJLLLJJJDDLLLJH########", "##########MMM####KMMMK####MMM##########", "##########MMM####KMMMK####MMM##########", "##########MMM####KMMMK####MMM##########", "###########I#####K#I#K#####I###########", "###########I#####K#I#K#####I###########", "###########I#####K#I#K#####I###########", "##########MMM####KMMMK####MMM##########", "##########MMM####KMMMK####MMM##########", "##########MMM####KMMMK####MMM##########", "########JJJJJJJJJJJJJJJJJJJJJJJ########", "##################KGK##################", "#######################################", "#######################################", "#######################################") 
            .aisle("#########HHHJJJJJJJJJJJJJJJHHH#########", "#########HHHJJJDDDLDLDDDJJJHHH#########", "############K#####MMM#####K############", "############K#####MMM#####K############", "############K#####MMM#####K############", "############K#####IDI#####K############", "############K#####ICI#####K############", "############K#####IDI#####K############", "############K#####MMM#####K############", "############K#####MMM#####K############", "############K#####MMM#####K############", "#########JJJJJJJJJJJJJJJJJJJJJ#########", "##################K#K##################", "#######################################", "#######################################", "#######################################") 
            .aisle("############HHHJJJJJJJJJHHH############", "############HHHJJJLLLJJJHHH############", "#################KMMMK#################", "#################KMMMK#################", "#################KMMMK#################", "#################K#I#K#################", "#################K#I#K#################", "#################K#I#K#################", "#################KMMMK#################", "#################KMMMK#################", "#################KMMMK#################", "############JJJJJJJJJJJJJJJ############", "##################K#K##################", "#######################################", "#######################################", "#######################################") 
            .aisle("###############HHHHHHHHH###############", "###############HHHHHHHHH###############", "#######################################", "#######################################", "#######################################", "#######################################", "#######################################", "#######################################", "#######################################", "#######################################", "#######################################", "###############JJJJJJJJJ###############", "#######################################", "#######################################", "#######################################", "#######################################") 	
            .where("A", Predicates.blocks("minecraft:red_nether_bricks")
                .or(Predicates.abilities(PartAbility.IMPORT_ITEMS).setMaxGlobalLimited(2))
                .or(Predicates.abilities(PartAbility.IMPORT_FLUIDS).setMaxGlobalLimited(3))
                .or(Predicates.abilities(PartAbility.EXPORT_ITEMS).setMaxGlobalLimited(1))
                .or(Predicates.abilities(PartAbility.MAINTENANCE).setExactLimit(1))
                .or(Predicates.abilities(PartAbility.INPUT_ENERGY).setMaxGlobalLimited(2)))	
            .where("B", Predicates.blocks("gtceu:heat_vent"))	
            .where("C", Predicates.blocks("kubejs:ancient_runicalium_casing"))	
            .where("D", Predicates.blocks("minecraft:red_nether_bricks"))	
            .where("E", Predicates.blocks("kubejs:runic_pathway_casing"))	
            .where("F", Predicates.blocks("kubejs:runic_transportation_casing"))	
            .where("G", Predicates.blocks("kubejs:runic_stabilization_casing"))	
            .where("H", Predicates.blocks("gtceu:steel_firebox_casing"))	
            .where("I", Predicates.blocks("gtceu:ancient_runicalium_frame"))	
            .where("J", Predicates.blocks("gtceu:atomic_casing"))	
            .where("K", Predicates.blocks("gtceu:void_frame"))	
            .where("L", Predicates.blocks("gtceu:steel_gearbox"))	
            .where("M", Predicates.blocks("kubejs:zalloy_coil_block"))	
            .where("#", Predicates.any())	
            .where("@", Predicates.controller(Predicates.blocks(definition.get())))	
            .where("N", Predicates.blocks("gtceu:fusion_glass"))
            .build())
        .workableCasingRenderer("minecraft:block/red_nether_bricks",
        "gtceu:block/machines/assembler", false);
});